//
//  SwiftyNSExceptionTests.swift
//  SwiftyNSException
//
//  Created by Sergej Jaskiewicz on 22.05.2017.
//  Copyright Â© 2017 Sergej Jaskiewicz. All rights reserved.
//

import XCTest
import SwiftyNSException

class SwiftyNSExceptionTests : XCTestCase {

    var exception: NSException {
        return NSException(name: .genericException,
                           reason: "Just an exception, nothing special")
    }

    class OrdinarySwiftClass : Equatable {

        let value: Int?

        init(_ value: Int?) {
            self.value = value
        }

        static func == (lhs: OrdinarySwiftClass,
                        rhs: OrdinarySwiftClass) -> Bool {

            return lhs.value == rhs.value
        }
    }

    enum OrdinarySwiftEnum : Equatable {
        case simpleCase
        case complexCase(Int?)

        static func == (lhs: OrdinarySwiftEnum,
                        rhs: OrdinarySwiftEnum) -> Bool {

            switch (lhs, rhs) {
            case (.simpleCase, .simpleCase):
                return true
            case (.complexCase(let lhs), .complexCase(let rhs)):
                return lhs == rhs
            default:
                return false
            }
        }
    }

    func testCatchNSExceptionInBlockReturningObjCClass() {

        let throwingBlock: () -> NSString = {
            self.exception.raise()
            return "Will not actually be returned."
        }

        do {

            _ = try handle(throwingBlock)

            XCTFail("Must never reach this point")

        } catch let caught as NSException {

            XCTAssertEqual(caught, exception)

        } catch {

            XCTFail("Must throw an NSException object")
        }
    }

    func testCatchNSExceptionInBlockReturningSwiftClass() {

        let throwingBlock: () -> OrdinarySwiftClass = {
            self.exception.raise()
            return OrdinarySwiftClass(42)
        }

        do {

            _ = try handle(throwingBlock)

            XCTFail("Must never reach this point")

        } catch let caught as NSException {

            XCTAssertEqual(caught, exception)

        } catch {

            XCTFail("Must throw an NSException object")
        }
    }

    func testCatchNSExceptionInBlockReturningSwiftEnum() {

        let throwingBlock: () -> OrdinarySwiftEnum = {
            self.exception.raise()
            return .complexCase(nil)
        }

        do {

            _ = try handle(throwingBlock)

            XCTFail("Must never reach this point")

        } catch let caught as NSException {

            XCTAssertEqual(caught, exception)

        } catch {
            
            XCTFail("Must throw an NSException object")
        }
    }

    func testGetResultOfBlockReturningObjCClass() {

        let expected: NSString = "Hello"

        let nonthrowingBlock: () -> NSString = {
            return expected
        }

        do {

            let returned = try handle(nonthrowingBlock)

            XCTAssertEqual(returned, expected)

        } catch {
            
            XCTFail("Must not throw")
        }
    }

    func testGetResultOfBlockReturningSwiftClass() {

        let expected = OrdinarySwiftClass(42)

        let nonthrowingBlock: () -> OrdinarySwiftClass = {
            return expected
        }

        do {

            let returned = try handle(nonthrowingBlock)

            XCTAssertEqual(returned, expected)

        } catch {

            XCTFail("Must not throw")
        }
    }

    func testGetResultOfBlockReturningSwiftEnum() {

        let expected = OrdinarySwiftEnum.complexCase(nil)

        let nonthrowingBlock: () -> OrdinarySwiftEnum = {
            return expected
        }

        do {

            let returned = try handle(nonthrowingBlock)

            XCTAssertEqual(returned, expected)

        } catch {
            
            XCTFail("Must not throw")
        }
    }

    func testGetResultOfBlockReturningOptionalResult() {

        let expected: Int? = nil

        let nonthrowingBlock: () -> Int? = {
            return expected
        }

        do {

            let returned = try handle(nonthrowingBlock)

            XCTAssertEqual(returned, expected)

        } catch {

            XCTFail("Must not throw")
        }
    }

    func testGetResultOfNonthrowingBlockReturningNSException() {

        let expected = exception

        let nonthrowingBlock: () -> NSException = {
            return expected
        }

        do {

            let returned = try handle(nonthrowingBlock)

            XCTAssertEqual(returned, expected)

        } catch {

            XCTFail("Must not throw")
        }
    }
}
